<?xml version="1.0" encoding="UTF-8"?>
<!-- This URDF was automatically created by SolidWorks to URDF Exporter! Originally created by Stephen Brawner (brawner@gmail.com) 
     Commit Version: 1.5.1-0-g916b5db  Build Version: 1.5.7152.31018
     For more information, please see http://wiki.ros.org/sw_urdf_exporter -->
<robot name="slam_car" xmlns:xacro="http://www.ros.org/wiki/xacro">

  <link name="base_footprint">
   <visual>
      <origin xyz="0 0 0" rpy="0 0 0" />
      <geometry>
        <box size="0.001 0.001 0.001" />
      </geometry>
    </visual>
  </link>

  <joint name="base_link_joint" type="fixed">
    <origin xyz="0 0 0" rpy="0 0 0" />
    <parent link="base_footprint"/>
    <child link="base_link" />
  </joint>


  <link name="base_link">
    <inertial>
      <origin xyz="0 0 0.04" rpy="0 0 0" />
      <mass value="0.59313" />
      <inertia
        ixx="0.0013364"
        ixy="4.824E-20"
        ixz="1.7974E-21"
        iyy="0.0038545"
        iyz="3.8567E-21"
        izz="0.0051839" />
    </inertial>
    <visual>
      <origin xyz="0 0 0" rpy="0 0 0" />
      <geometry>
        <mesh filename="package://slam_car/meshes/base_link.STL" />
      </geometry>
      <material name="">
        <color rgba="1 1 1 1" />
      </material>
    </visual>
    <collision>
      <origin xyz="0 0 0" rpy="0 0 0" />
      <geometry>
        <mesh filename="package://slam_car/meshes/base_link.STL" />
      </geometry>
    </collision>
  </link>

  <link name="link_wheel_FL">
    <inertial>
      <origin xyz="0 0.012 0" rpy="0 0 0" />
      <mass value="0.10053" />
      <inertia
        ixx="4.3563E-05"
        ixy="1.1294E-21"
        ixz="-1.6941E-21"
        iyy="8.0425E-05"
        iyz="-7.0586E-23"
        izz="4.3563E-05" />
    </inertial>
    <visual>
      <origin xyz="0 0 0" rpy="0 0 0" />
      <geometry>
        <mesh filename="package://slam_car/meshes/link_wheel_FL.STL" />
      </geometry>
      <material name="">
        <color rgba="1 1 1 1" />
      </material>
    </visual>
    <collision>
      <origin xyz="0 0 0" rpy="0 0 0" />
      <geometry>
        <mesh filename="package://slam_car/meshes/link_wheel_FL.STL" />
      </geometry>
    </collision>
  </link>

  <joint
    name="joint_wheel_FL"
    type="continuous">
    <origin
      xyz="0.08 0.08 0.04"
      rpy="0 0 0" />
    <parent
      link="base_link" />
    <child
      link="link_wheel_FL" />
    <axis
      xyz="0 1 0" />
  </joint>

  <link name="link_wheel_FR">
    <inertial>
      <origin xyz="0 -0.012 0" rpy="0 0 0" />
      <mass value="0.10053" />
      <inertia
        ixx="4.3563E-05"
        ixy="-7.2158E-38"
        ixz="-5.294E-23"
        iyy="8.0425E-05"
        iyz="7.9908E-38"
        izz="4.3563E-05" />
    </inertial>
    <visual>
      <origin xyz="0 0 0" rpy="0 0 0" />
      <geometry>
        <mesh filename="package://slam_car/meshes/link_wheel_FR.STL" />
      </geometry>
      <material name="">
        <color rgba="1 1 1 1" />
      </material>
    </visual>
    <collision>
      <origin xyz="0 0 0" rpy="0 0 0" />
      <geometry>
        <mesh filename="package://slam_car/meshes/link_wheel_FR.STL" />
      </geometry>
    </collision>
  </link>

  <joint name="joint_wheel_FR" type="continuous">
    <origin xyz="0.0800000000000013 -0.0799999999999997 0.04" rpy="0 0 0" />
    <parent link="base_link" />
    <child link="link_wheel_FR" />
    <axis xyz="0 1 0" />
  </joint>

  <link name="link_wheel_BL">
    <inertial>
      <origin xyz="0 0.012 0" rpy="0 0 0" />
      <mass value="0.10053" />
      <inertia
        ixx="4.3563E-05"
        ixy="5.6469E-22"
        ixz="5.6469E-22"
        iyy="8.0425E-05"
        iyz="-4.2977E-37"
        izz="4.3563E-05" />
    </inertial>
    <visual>
      <origin xyz="0 0 0" rpy="0 0 0" />
      <geometry>
        <mesh filename="package://slam_car/meshes/link_wheel_BL.STL" />
      </geometry>
      <material name="">
        <color rgba="1 1 1 1" />
      </material>
    </visual>
    <collision>
      <origin xyz="0 0 0" rpy="0 0 0" />
      <geometry>
        <mesh filename="package://slam_car/meshes/link_wheel_BL.STL" />
      </geometry>
    </collision>
  </link>

  <joint name="joint_wheel_BL" type="continuous">
    <origin xyz="-0.08 0.08 0.04" rpy="0 0 0" />
    <parent link="base_link" />
    <child link="link_wheel_BL" />
    <axis xyz="0 1 0" />
  </joint>

  <link name="link_wheel_BR">
    <inertial>
      <origin xyz="0 -0.012 0" rpy="0 0 0" />
      <mass value="0.10053" />
      <inertia
        ixx="4.3563E-05"
        ixy="-7.3468E-38"
        ixz="-6.1763E-23"
        iyy="8.0425E-05"
        iyz="-4.5918E-39"
        izz="4.3563E-05" />
    </inertial>
    <visual>
      <origin xyz="0 0 0" rpy="0 0 0" />
      <geometry>
        <mesh filename="package://slam_car/meshes/link_wheel_BR.STL" />
      </geometry>
      <material name="">
        <color rgba="1 1 1 1" />
      </material>
    </visual>
    <collision>
      <origin xyz="0 0 0" rpy="0 0 0" />
      <geometry>
        <mesh filename="package://slam_car/meshes/link_wheel_BR.STL" />
      </geometry>
    </collision>
  </link>

  <joint name="joint_wheel_BR" type="continuous">
    <origin xyz="-0.08 -0.08 0.04" rpy="0 0 0" />
    <parent link="base_link" />
    <child link="link_wheel_BR" />
    <axis xyz="0 1 0" />
  </joint>

  <link name="camera">
    <inertial>
      <origin xyz="-0.0050423 0 0.01" rpy="0 0 0" />
      <mass value="0.003959" />
      <inertia
        ixx="2.6388E-07"
        ixy="1.0006E-21"
        ixz="6.9411E-22"
        iyy="1.6457E-07"
        iyz="-8.1106E-24"
        izz="1.6457E-07" />
    </inertial>
    <visual>
      <origin xyz="0 0 0" rpy="0 0 0" />
      <geometry>
        <mesh filename="package://slam_car/meshes/camera.STL" />
      </geometry>
      <material name="">
        <color rgba="1 1 1 1" />
      </material>
    </visual>
    <collision>
      <origin xyz="0 0 0" rpy="0 0 0" />
      <geometry>
        <mesh filename="package://slam_car/meshes/camera.STL" />
      </geometry>
    </collision>
  </link>

  <joint name="joint_camera" type="fixed">
    <origin xyz="0.15 0 0.03" rpy="0 0 0" />
    <parent link="base_link" />
    <child link="camera" />
    <axis xyz="0 0 0" />
  </joint>

  <link name="camera_depth_optical_frame" />

  <joint name="camera_depth_optical_joint" type="fixed">
    <origin rpy="-1.57079632679 0 -1.57079632679" xyz="0 0 0" />
    <parent link="camera"/>
    <child link="camera_depth_optical_frame" />
  </joint>

  <!--laser_link-->
  <link name="hokuyo">
    <collision>
      <origin xyz="0 0 0" rpy="0 0 0"/>
      <geometry>
        <mesh filename="package://slam_car/meshes/hokuyo.dae"/>
      </geometry>
    </collision>
    <visual>
      <origin xyz="0 0 0" rpy="0 0 0"/>
      <geometry>
        <mesh filename="package://slam_car/meshes/hokuyo.dae"/>
      </geometry>
      <material name="red">
        <color rgba="1.0 0 0 1.0"/>
      </material>
    </visual>
    <inertial>
      <mass value="0.1" />
      <origin xyz="0.00 0.0 0.0" rpy="0 1.57 0"/>
      <inertia ixx="1e-6" ixy="0" ixz="0" iyy="1e-6" iyz="0" izz="1e-6" />
    </inertial>
  </link>

  <joint name="hokuyo_joint" type="fixed">
    <axis xyz="0 0 0" />
    <origin xyz="0 0 0.1" rpy="0 0 0"/>
    <parent link="base_link"/>
    <child link="hokuyo"/>
  </joint>

  <gazebo>
    <plugin name="skid_steer_drive_controller" filename="libgazebo_ros_skid_steer_drive.so">
	<alwaysOn>true</alwaysOn>
        <updateRate>100.0</updateRate>
        <robotNamespace>/</robotNamespace>
        <leftFrontJoint>joint_wheel_FL</leftFrontJoint>
        <rightFrontJoint>joint_wheel_FR</rightFrontJoint>
        <leftRearJoint>joint_wheel_BL</leftRearJoint>
        <rightRearJoint>joint_wheel_BR</rightRearJoint>
        <wheelSeparation>0.16</wheelSeparation>
        <wheelDiameter>0.08</wheelDiameter>
        <robotBaseFrame>base_footprint</robotBaseFrame>
        <torque>20</torque>
        <commandTopic>cmd_vel</commandTopic>
    	<odometryTopic>odom</odometryTopic>
    	<odometryFrame>odom</odometryFrame>
    	<broadcastTF>1</broadcastTF>
    </plugin>
  </gazebo>

  <!--RGBD camera -->
  <gazebo reference="camera">
   <sensor type="depth" name="camera">
     <always_on>true</always_on>
     <visualize>false</visualize>
     <update_rate>15.0</update_rate>
     <camera name="front">
       <horizontal_fov>1.047197</horizontal_fov>
       <image>
         <!-- openni_kinect plugin works only with BGR8 -->
         <format>B8G8R8</format>
         <width>400</width>
         <height>300</height>
       </image>
       <clip>
         <near>0.01</near>
         <far>8</far>
       </clip>
     </camera>
     <plugin name="camera_controller" filename="libgazebo_ros_openni_kinect.so">
       <baseline>0.1</baseline>
       <alwaysOn>true</alwaysOn>
       <updateRate>15.0</updateRate>
       <cameraName>camera</cameraName>
       <imageTopicName>/camera/rgb/image_raw</imageTopicName>
       <cameraInfoTopicName>/camera/rgb/camera_info</cameraInfoTopicName>
       <depthImageTopicName>/camera/depth/image_raw</depthImageTopicName>
       <depthImageCameraInfoTopicName>/camera/depth_registered/camera_info</depthImageCameraInfoTopicName>
       <pointCloudTopicName>/camera/depth_registered/points</pointCloudTopicName>
       <frameName>camera_depth_optical_frame</frameName>
       <pointCloudCutoff>0.35</pointCloudCutoff>
       <pointCloudCutoffMax>4.5</pointCloudCutoffMax>
       <CxPrime>0</CxPrime>
       <Cx>0</Cx>
       <Cy>0</Cy>
       <focalLength>0</focalLength>
       <hackBaseline>0</hackBaseline>
     </plugin>
   </sensor>
  </gazebo>

 <!-- hokuyo -->
  <gazebo reference="hokuyo">
    <sensor type="ray" name="head_hokuyo_sensor">
      <pose>0 0 0 0 0 0</pose>
      <visualize>false</visualize>
      <update_rate>40</update_rate>
      <ray>
        <scan>
          <horizontal>
            <samples>720</samples>
            <resolution>1</resolution>
            <min_angle>-1.570796</min_angle>
            <max_angle>1.570796</max_angle>
          </horizontal>
        </scan>
        <range>
          <min>0.10</min>
          <max>30.0</max>
          <resolution>0.01</resolution>
        </range>
        <noise>
          <type>gaussian</type>
          <!-- Noise parameters based on published spec for Hokuyo laser
               achieving "+-30mm" accuracy at range < 10m.  A mean of 0.0m and
               stddev of 0.01m will put 99.7% of samples within 0.03m of the true
               reading. -->
          <mean>0.0</mean>
          <stddev>0.01</stddev>
        </noise>
      </ray>
      <plugin name="gazebo_ros_head_hokuyo_controller" filename="libgazebo_ros_laser.so">
        <topicName>/slam_car/laser/scan</topicName>
        <frameName>hokuyo</frameName>
      </plugin>
    </sensor>
  </gazebo>
</robot>
